<?xml version="1.0"?>
<robot xmlns:xacro="http://www.ros.org/wiki/xacro" name="my_robot">

  <xacro:property name="M_PI" value="3.1415926535897931" />

  <xacro:arg name="robot_name" default="my_robot"/>
  <xacro:arg name="prefix" default=""/>
  <xacro:arg name="use_gazebo" default="false"/>

  <xacro:include filename="$(find my_robot_description)/urdf/sensors/lidar.urdf.xacro"/>
  <xacro:include filename="$(find my_robot_description)/urdf/sensors/imu.urdf.xacro"/>
  <xacro:include filename="$(find my_robot_description)/urdf/sensors/rgbd_camera.urdf.xacro"/>

  <link name="base_link">
    <visual>
      <origin xyz="0 0 0" rpy="0 0 0" />
      <geometry>
        <mesh filename="package://my_robot_description/meshes/rosmaster_x3/visual/base_link.STL" />
      </geometry>
      <material name=""><color rgba="0.956862745098039 0.956862745098039 0.956862745098039 1" /></material>
    </visual>
    <collision>
      <origin xyz="0 0 0" rpy="0 0 0" />
      <geometry>
        <mesh filename="package://my_robot_description/meshes/rosmaster_x3/visual/base_link.STL" />
      </geometry>
    </collision>
  </link>

  <link name="LB_above_link">
    <inertial>
      <origin xyz="-0.0043511846352115 -1.25307952624117E-06 -0.017637217770487" rpy="0 0 0" />
      <mass value="0.0613934593613199" />
      <inertia ixx="6.84020280641822E-05" ixy="-3.68996328607424E-09" ixz="-1.10186894346824E-05" iyy="7.08258211057998E-05" iyz="-4.84220030273478E-09" izz="6.96936246250135E-05" />
    </inertial>
    <visual><origin xyz="0 0 0" rpy="0 0 0" /><geometry><mesh filename="package://my_robot_description/meshes/rosmaster_x3/visual/LB_above_link.STL" /></geometry><material name=""><color rgba="0.792156862745098 0.819607843137255 0.933333333333333 1" /></material></visual>
    <collision><origin xyz="0 0 0" rpy="0 0 0" /><geometry><mesh filename="package://my_robot_description/meshes/rosmaster_x3/visual/LB_above_link.STL" /></geometry></collision>
  </link>
  <joint name="LB_above_joint" type="continuous">
    <origin xyz="-0.399729040475105 0.244251423359786 -0.157999999999999" rpy="0 0 0" />
    <parent link="base_link" /><child link="LB_above_link" /><axis xyz="0 0 -1" />
    <limit effort="10" velocity="10" /><dynamics damping="0.1" friction="0.1" />
  </joint>

  <link name="LB_below_link">
    <inertial>
      <origin xyz="-5.03917192809511E-06 -3.18265486187741E-09 -0.0318999292944038" rpy="0 0 0" />
      <mass value="0.282878366071618" />
      <inertia ixx="0.00037220906936453" ixy="1.95924077982568E-15" ixz="-6.3090182725381E-10" iyy="0.000372204012630136" iyz="2.56610051274169E-12" izz="0.00069227461337227" />
    </inertial>
    <visual><origin xyz="0 0 0" rpy="0 0 0" /><geometry><mesh filename="package://my_robot_description/meshes/rosmaster_x3/visual/LB_below_link.STL" /></geometry><material name=""><color rgba="0.596078431372549 0.619607843137255 0.631372549019608 1" /></material></visual>
    <collision><origin xyz="0 0 0" rpy="0 0 0" /><geometry><mesh filename="package://my_robot_description/meshes/rosmaster_x3/visual/LB_below_link.STL" /></geometry></collision>
  </link>
  <joint name="LB_below_joint" type="continuous">
    <origin xyz="-0.0295228180170212 0.0319 -0.0925076162853427" rpy="-1.5707963267949 0 0" />
    <parent link="LB_above_link" /><child link="LB_below_link" /><axis xyz="0 0 -1" />
    <limit effort="10" velocity="10" /><dynamics damping="0.1" friction="0.1" />
  </joint>

  <link name="RB_above_link">
    <inertial>
      <origin xyz="-0.00435118463521134 -1.25307952641984E-06 -0.0176372177704868" rpy="0 0 0" />
      <mass value="0.0613934593613195" />
      <inertia ixx="6.84020280641811E-05" ixy="-3.6899632859696E-09" ixz="-1.10186894346818E-05" iyy="7.0825821105799E-05" iyz="-4.84220030288135E-09" izz="6.96936246250134E-05" />
    </inertial>
    <visual><origin xyz="0 0 0" rpy="0 0 0" /><geometry><mesh filename="package://my_robot_description/meshes/rosmaster_x3/visual/RB_above_link.STL" /></geometry><material name=""><color rgba="0.792156862745098 0.819607843137255 0.933333333333333 1" /></material></visual>
    <collision><origin xyz="0 0 0" rpy="0 0 0" /><geometry><mesh filename="package://my_robot_description/meshes/rosmaster_x3/visual/RB_above_link.STL" /></geometry></collision>
  </link>
  <joint name="RB_above_joint" type="continuous">
    <origin xyz="-0.39972904047509 -0.244748576640214 -0.157999999999998" rpy="0 0 0" />
    <parent link="base_link" /><child link="RB_above_link" /><axis xyz="0 0 1" />
    <limit effort="10" velocity="10" /><dynamics damping="0.1" friction="0.1" />
  </joint>

  <link name="RB_below_link">
    <inertial>
      <origin xyz="-5.03917192817838E-06 -3.18265483412183E-09 0.0345000707055961" rpy="0 0 0" />
      <mass value="0.282878366071619" />
      <inertia ixx="0.000372209069364545" ixy="1.95921717621499E-15" ixz="-6.30901829737797E-10" iyy="0.000372204012630151" iyz="2.56610086000659E-12" izz="0.000692274613372272" />
    </inertial>
    <visual><origin xyz="0 0 0" rpy="0 0 0" /><geometry><mesh filename="package://my_robot_description/meshes/rosmaster_x3/visual/RB_below_link.STL" /></geometry><material name=""><color rgba="0.596078431372549 0.619607843137255 0.631372549019608 1" /></material></visual>
    <collision><origin xyz="0 0 0" rpy="0 0 0" /><geometry><mesh filename="package://my_robot_description/meshes/rosmaster_x3/visual/RB_below_link.STL" /></geometry></collision>
  </link>
  <joint name="RB_below_joint" type="continuous">
    <origin xyz="-0.0295228180170215 -0.0345 -0.0925076162853426" rpy="-1.5707963267949 0 0" />
    <parent link="RB_above_link" /><child link="RB_below_link" /><axis xyz="0 0 1" />
    <limit effort="10" velocity="10" /><dynamics damping="0.1" friction="0.1" />
  </joint>

  <link name="RM_link">
    <inertial>
      <origin xyz="0 0 0.0157545783722145" rpy="0 0 0" />
      <mass value="0.0777558845808905" />
      <inertia ixx="3.03837077610577E-05" ixy="0" ixz="0" iyy="3.03837077610577E-05" iyz="0" izz="5.25266191826487E-05" />
    </inertial>
    <visual><origin xyz="0 0 0" rpy="0 0 0" /><geometry><mesh filename="package://my_robot_description/meshes/rosmaster_x3/visual/RM_link.STL" /></geometry><material name=""><color rgba="0.749019607843137 0.749019607843137 0.749019607843137 1" /></material></visual>
    <collision><origin xyz="0 0 0" rpy="0 0 0" /><geometry><mesh filename="package://my_robot_description/meshes/rosmaster_x3/visual/RM_link.STL" /></geometry></collision>
  </link>
  <joint name="RM_joint" type="continuous">
    <origin xyz="-0.0374114525207011 -0.305348576640202 -0.233000000000002" rpy="-1.57079632679488 0 0" />
    <parent link="base_link" /><child link="RM_link" /><axis xyz="0 0 1" />
    <limit effort="10" velocity="10" /><dynamics damping="0.1" friction="0.1" />
  </joint>

  <link name="LM_link">
    <inertial>
      <origin xyz="0 0 -0.0157545783722145" rpy="0 0 0" />
      <mass value="0.0777558845808906" />
      <inertia ixx="3.03837077610577E-05" ixy="0" ixz="0" iyy="3.03837077610577E-05" iyz="0" izz="5.25266191826487E-05" />
    </inertial>
    <visual><origin xyz="0 0 0" rpy="0 0 0" /><geometry><mesh filename="package://my_robot_description/meshes/rosmaster_x3/visual/LM_link.STL" /></geometry><material name=""><color rgba="0.745098039215686 0.737254901960784 0.729411764705882 1" /></material></visual>
    <collision><origin xyz="0 0 0" rpy="0 0 0" /><geometry><mesh filename="package://my_robot_description/meshes/rosmaster_x3/visual/LM_link.STL" /></geometry></collision>
  </link>
  <joint name="LM_joint" type="continuous">
    <origin xyz="-0.0374114525207191 0.304851423359795 -0.23299999999999" rpy="-1.57079632679487 0 0" />
    <parent link="base_link" /><child link="LM_link" /><axis xyz="0 0 -1" />
    <limit effort="10" velocity="10" /><dynamics damping="0.1" friction="0.1" />
  </joint>

  <link name="LF_above_link">
    <inertial>
      <origin xyz="-0.00584419614752874 0 -0.028396528181358" rpy="0 0 0" />
      <mass value="0.158197868402843" />
      <inertia ixx="8.20585646900215E-05" ixy="0" ixz="-1.40536491272341E-05" iyy="0.000100197139407139" iyz="0" izz="0.000101365612600187" />
    </inertial>
    <visual><origin xyz="0 0 0" rpy="0 0 0" /><geometry><mesh filename="package://my_robot_description/meshes/rosmaster_x3/visual/LF_above_link.STL" /></geometry><material name=""><color rgba="0.666666666666667 0.698039215686274 0.768627450980392 1" /></material></visual>
    <collision><origin xyz="0 0 0" rpy="0 0 0" /><geometry><mesh filename="package://my_robot_description/meshes/rosmaster_x3/visual/LF_above_link.STL" /></geometry></collision>
  </link>
  <joint name="LF_above_joint" type="continuous">
    <origin xyz="0.399770959524882 0.274751423359812 -0.136350000000002" rpy="0 0 0" />
    <parent link="base_link" /><child link="LF_above_link" /><axis xyz="0 0 1" />
    <limit effort="10" velocity="10" /><dynamics damping="0.1" friction="0.1" />
  </joint>

  <link name="LF_below_link">
    <inertial>
      <origin xyz="0 0 -0.0338249999999973" rpy="0 0 0" />
      <mass value="0.50932693354864" />
      <inertia ixx="0.00097947117418515" ixy="0" ixz="0" iyy="0.00097947117418515" iyz="0" izz="0.00179052978188696" />
    </inertial>
    <visual><origin xyz="0 0 0" rpy="0 0 0" /><geometry><mesh filename="package://my_robot_description/meshes/rosmaster_x3/visual/LF_below_link.STL" /></geometry><material name=""><color rgba="0.8 0.549019607843137 0.0941176470588235 1" /></material></visual>
    <collision><origin xyz="0 0 0" rpy="0 0 0" /><geometry><mesh filename="package://my_robot_description/meshes/rosmaster_x3/visual/LF_below_link.STL" /></geometry></collision>
  </link>
  <joint name="LF_below_joint" type="continuous">
    <origin xyz="-0.0343013158455636 0.0338249999999973 -0.100400000000001" rpy="-1.5707963267949 0 0" />
    <parent link="LF_above_link" /><child link="LF_below_link" /><axis xyz="0 0 -1" />
    <limit effort="10" velocity="10" /><dynamics damping="0.1" friction="0.1" />
  </joint>

  <link name="RF_above_link">
    <inertial>
      <origin xyz="-0.00584419614752885 0 -0.028396528181358" rpy="0 0 0" />
      <mass value="0.158197868402843" />
      <inertia ixx="8.20585646900215E-05" ixy="0" ixz="-1.40536491272341E-05" iyy="0.000100197139407139" iyz="0" izz="0.000101365612600187" />
    </inertial>
    <visual><origin xyz="0 0 0" rpy="0 0 0" /><geometry><mesh filename="package://my_robot_description/meshes/rosmaster_x3/visual/RF_above_link.STL" /></geometry><material name=""><color rgba="0.666666666666667 0.698039215686274 0.768627450980392 1" /></material></visual>
    <collision><origin xyz="0 0 0" rpy="0 0 0" /><geometry><mesh filename="package://my_robot_description/meshes/rosmaster_x3/visual/RF_above_link.STL" /></geometry></collision>
  </link>
  <joint name="RF_above_joint" type="continuous">
    <origin xyz="0.399770959524897 -0.275248576640188 -0.136350000000001" rpy="0 0 0" />
    <parent link="base_link" /><child link="RF_above_link" /><axis xyz="0 0 1" />
    <limit effort="10" velocity="10" /><dynamics damping="0.1" friction="0.1" />
  </joint>

  <link name="RF_below_link">
    <inertial>
      <origin xyz="0 0 0.037" rpy="0 0 0" />
      <mass value="0.50932693354864" />
      <inertia ixx="0.00097947117418515" ixy="0" ixz="0" iyy="0.00097947117418515" iyz="0" izz="0.00179052978188696" />
    </inertial>
    <visual><origin xyz="0 0 0" rpy="0 0 0" /><geometry><mesh filename="package://my_robot_description/meshes/rosmaster_x3/visual/RF_below_link.STL" /></geometry><material name=""><color rgba="0.8 0.549019607843137 0.0941176470588235 1" /></material></visual>
    <collision><origin xyz="0 0 0" rpy="0 0 0" /><geometry><mesh filename="package://my_robot_description/meshes/rosmaster_x3/visual/RF_below_link.STL" /></geometry></collision>
  </link>
  <joint name="RF_below_joint" type="continuous">
    <origin xyz="-0.0343013158455587 -0.037 -0.1004" rpy="-1.57079632679491 0 0" />
    <parent link="RF_above_link" /><child link="RF_below_link" /><axis xyz="0 0 1" />
    <limit effort="10" velocity="10" /><dynamics damping="0.1" friction="0.1" />
  </joint>

  <link name="Arm_base_link">
    <inertial>
      <origin xyz="0.0743 0.002 0.0303" rpy="0 0 0" />
      <mass value="0.5969" />
      <inertia ixx="0.00088" ixy="0" ixz="0" iyy="0.00084" iyz="0" izz="0.0012" />
    </inertial>
    <visual><origin xyz="0 0 0" rpy="0 0 0" /><geometry><mesh filename="package://my_robot_description/meshes/rosmaster_x3/visual/Arm_base_link.STL" /></geometry><material name=""><color rgba="0.792156862745098 0.819607843137255 0.933333333333333 1" /></material></visual>
    <collision><origin xyz="0 0 0" rpy="0 0 0" /><geometry><mesh filename="package://my_robot_description/meshes/rosmaster_x3/visual/Arm_base_link.STL" /></geometry></collision>
  </link>
  <joint name="Arm_base_joint" type="fixed">
    <origin xyz="0.202476412824287 0.0505838494416569 0.503000000000002" rpy="0 0 0" />
    <parent link="base_link" /><child link="Arm_base_link" />
  </joint>

  <link name="j1_arm_link">
    <inertial>
      <origin xyz="0.0042 0.0423 0.0631" rpy="0 0 0" />
      <mass value="0.4153" />
      <inertia ixx="0.00099" ixy="0" ixz="0" iyy="0.00049" iyz="0" izz="0.0011" />
    </inertial>
    <visual><origin xyz="0 0 0" rpy="0 0 0" /><geometry><mesh filename="package://my_robot_description/meshes/rosmaster_x3/visual/j1_arm_link.STL" /></geometry><material name=""><color rgba="0.0117647058823529 0.207843137254902 1 1" /></material></visual>
    <collision><origin xyz="0 0 0" rpy="0 0 0" /><geometry><mesh filename="package://my_robot_description/meshes/rosmaster_x3/visual/j1_arm_link.STL" /></geometry></collision>
  </link>
  <joint name="j1_arm_joint" type="revolute">
    <origin xyz="0.107294546700604 0.00166757391815214 0.0234999999999956" rpy="0 0 0" />
    <parent link="Arm_base_link" /><child link="j1_arm_link" /><axis xyz="0 0 1" />
    <limit lower="-3.15" upper="3.15" effort="10" velocity="10" /><dynamics damping="0.1" friction="0.1" />
  </joint>

  <link name="j2_arm_link">
    <inertial>
      <origin xyz="0.0493 -0.1271 -0.0677" rpy="0 0 0" />
      <mass value="0.4644" />
      <inertia ixx="0.0008" ixy="0" ixz="0" iyy="0.0003" iyz="0" izz="0.001" />
    </inertial>
    <visual><origin xyz="0 0 0" rpy="0 0 0" /><geometry><mesh filename="package://my_robot_description/meshes/rosmaster_x3/visual/j2_arm_link.STL" /></geometry><material name=""><color rgba="0.0117647058823529 0.207843137254902 1 1" /></material></visual>
    <collision><origin xyz="0 0 0" rpy="0 0 0" /><geometry><mesh filename="package://my_robot_description/meshes/rosmaster_x3/visual/j2_arm_link.STL" /></geometry></collision>
  </link>
  <joint name="j2_arm_joint" type="revolute">
    <origin xyz="0.0183985052903536 0.123850818237505 0.0860000000000007" rpy="-1.5707963267949 0 0.0406846778022905" />
    <parent link="j1_arm_link" /><child link="j2_arm_link" /><axis xyz="0 0 -1" />
    <limit lower="-3.15" upper="3.15" effort="10" velocity="10" /><dynamics damping="0.1" friction="0.1" />
  </joint>

  <link name="j3_arm_link">
    <inertial>
      <origin xyz="0.0144 -0.0133 -0.0288" rpy="0 0 0" />
      <mass value="0.309" />
      <inertia ixx="0.00033" ixy="0" ixz="0" iyy="0.00036" iyz="0" izz="0.00044" />
    </inertial>
    <visual><origin xyz="0 0 0" rpy="0 0 0" /><geometry><mesh filename="package://my_robot_description/meshes/rosmaster_x3/visual/j3_arm_link.STL" /></geometry><material name=""><color rgba="0.0117647058823529 0.207843137254902 1 1" /></material></visual>
    <collision><origin xyz="0 0 0" rpy="0 0 0" /><geometry><mesh filename="package://my_robot_description/meshes/rosmaster_x3/visual/j3_arm_link.STL" /></geometry></collision>
  </link>
  <joint name="j3_arm_joint" type="revolute">
    <origin xyz="0.120758547102581 -0.251059130342023 -0.0847999999999965" rpy="0 0 0" />
    <parent link="j2_arm_link" /><child link="j3_arm_link" /><axis xyz="0 0 1" />
    <limit lower="-3.15" upper="3.15" effort="10" velocity="10" /><dynamics damping="0.1" friction="0.1" />
  </joint>

  <link name="j4_arm_link">
    <inertial>
      <origin xyz="0.0245 0.001 0.0629" rpy="0 0 0" />
      <mass value="0.2149" />
      <inertia ixx="0.00024" ixy="0" ixz="0" iyy="0.00022" iyz="0" izz="0.00013" />
    </inertial>
    <visual><origin xyz="0 0 0" rpy="0 0 0" /><geometry><mesh filename="package://my_robot_description/meshes/rosmaster_x3/visual/j4_arm_link.STL" /></geometry><material name=""><color rgba="0.792156862745098 0.819607843137255 0.933333333333333 1" /></material></visual>
    <collision><origin xyz="0 0 0" rpy="0 0 0" /><geometry><mesh filename="package://my_robot_description/meshes/rosmaster_x3/visual/j4_arm_link.STL" /></geometry></collision>
  </link>
  <joint name="j4_arm_joint" type="revolute">
    <origin xyz="0.0734332921250569 -0.039343412506755 -0.0352000000000054" rpy="1.5707963267787 1.56845608998159 1.62831773689441" />
    <parent link="j3_arm_link" /><child link="j4_arm_link" /><axis xyz="0 0 -1" />
    <limit lower="-3.15" upper="3.15" effort="10" velocity="10" /><dynamics damping="0.1" friction="0.1" />
  </joint>

  <link name="j5_arm_link">
    <inertial>
      <origin xyz="-0.0038 -0.0005 0.0405" rpy="0 0 0" />
      <mass value="0.0919" />
      <inertia ixx="5.9E-05" ixy="0" ixz="0" iyy="7.6E-05" iyz="0" izz="7.9E-05" />
    </inertial>
    <visual><origin xyz="0 0 0" rpy="0 0 0" /><geometry><mesh filename="package://my_robot_description/meshes/rosmaster_x3/visual/j5_arm_link.STL" /></geometry><material name=""><color rgba="0.745098039215686 0.737254901960784 0.729411764705882 1" /></material></visual>
    <collision><origin xyz="0 0 0" rpy="0 0 0" /><geometry><mesh filename="package://my_robot_description/meshes/rosmaster_x3/visual/j5_arm_link.STL" /></geometry></collision>
  </link>
  <joint name="j5_arm_joint" type="revolute">
    <origin xyz="0.0460019581798649 0.00369355433397323 0.155300000000005" rpy="0.749397627579391 -1.57079631189374 -0.669411330897685" />
    <parent link="j4_arm_link" /><child link="j5_arm_link" /><axis xyz="0 0 1" />
    <limit lower="-3.15" upper="3.15" effort="10" velocity="10" /><dynamics damping="0.1" friction="0.1" />
  </joint>

  <link name="j6_arm_link">
    <inertial>
      <origin xyz="0 0 -0.0495" rpy="0 0 0" />
      <mass value="0.0429" />
      <inertia ixx="8.4E-06" ixy="0" ixz="0" iyy="8.4E-06" iyz="0" izz="1.2E-05" />
    </inertial>
    <visual><origin xyz="0 0 0" rpy="0 0 0" /><geometry><mesh filename="package://my_robot_description/meshes/rosmaster_x3/visual/j6_arm_link.STL" /></geometry><material name=""><color rgba="0.282352941176471 0.27843137254902 0.23921568627451 1" /></material></visual>
    <collision><origin xyz="0 0 0" rpy="0 0 0" /><geometry><mesh filename="package://my_robot_description/meshes/rosmaster_x3/visual/j6_arm_link.STL" /></geometry></collision>
  </link>
  <joint name="j6_arm_joint" type="revolute">
    <origin xyz="0.0506489179242555 0.00597386919024678 0.046149999999993" rpy="-1.5707963267948 1.49597339048923 -1.45339211088573" />
    <parent link="j5_arm_link" /><child link="j6_arm_link" /><axis xyz="0 0 -1" />
    <limit lower="-3.15" upper="3.15" effort="10" velocity="10" /><dynamics damping="0.1" friction="0.1" />
  </joint>

  <link name="camera_holder_link">
    <visual>
        <origin xyz="0 0 0" rpy="0 0 0" />
        <geometry>
            <mesh filename="package://my_robot_description/meshes/rosmaster_x3/visual/camera_holder.STL" scale="0.001 0.001 0.001" />
        </geometry>
        <material name="holder_color"><color rgba="0.2 0.2 0.2 1" /></material>
    </visual>
    <collision>
        <origin xyz="0 0 0" rpy="0 0 0" />
        <geometry>
            <mesh filename="package://my_robot_description/meshes/rosmaster_x3/visual/camera_holder.STL" scale="0.001 0.001 0.001" />
        </geometry>
    </collision>
  </link>
  <joint name="camera_holder_joint" type="fixed">
    <parent link="base_link" /><child link="camera_holder_link" />
    <origin xyz="0.252 -0.211 0.576" rpy="3.1457 0 4.7165" /> 
  </joint>

  <link name="end_effector_link">
    <visual>
        <origin xyz="0 0 0" rpy="0 0 0" />
        <geometry>
            <mesh filename="package://my_robot_description/meshes/rosmaster_x3/visual/end_effector.stl" scale="0.001 0.001 0.001"/>
        </geometry>
        <material name="ee_color"><color rgba="0 0 0 1" /></material>
    </visual>
    <collision>
        <origin xyz="0 0 0" rpy="0 0 0" />
        <geometry>
            <mesh filename="package://my_robot_description/meshes/rosmaster_x3/visual/end_effector.stl" scale="0.001 0.001 0.001"/>
        </geometry>
    </collision>
  </link>
  <joint name="end_effector_fixed_joint" type="fixed">
    <parent link="j6_arm_link" /><child link="end_effector_link" /> 
    <origin xyz="0.045 -0.026 0.135" rpy="0 3.1457 0" /> 
  </joint>

  <gazebo>
    <plugin filename="gz_ros2_control-system" name="gz_ros2_control::GazeboSimROS2ControlPlugin">
      <parameters>$(find my_robot_control)/config/ros2_controllers.yaml</parameters>
      <controller_manager_node_name>controller_manager</controller_manager_node_name>
    </plugin>
  </gazebo>

  <ros2_control name="MockSystem" type="system">
    <hardware>
      <plugin>mock_components/GenericSystem</plugin>
    </hardware>
    <joint name="j1_arm_joint">
      <command_interface name="position"><param name="min">-3.15</param><param name="max">3.15</param></command_interface>
      <command_interface name="velocity"><param name="min">-10.0</param><param name="max">10.0</param></command_interface>
      <state_interface name="position"/><state_interface name="velocity"/>
    </joint>
    <joint name="j2_arm_joint">
      <command_interface name="position"><param name="min">-3.15</param><param name="max">3.15</param></command_interface>
      <command_interface name="velocity"><param name="min">-10.0</param><param name="max">10.0</param></command_interface>
      <state_interface name="position"/><state_interface name="velocity"/>
    </joint>
    <joint name="j3_arm_joint">
      <command_interface name="position"><param name="min">-3.15</param><param name="max">3.15</param></command_interface>
      <command_interface name="velocity"><param name="min">-10.0</param><param name="max">10.0</param></command_interface>
      <state_interface name="position"/><state_interface name="velocity"/>
    </joint>
    <joint name="j4_arm_joint">
      <command_interface name="position"><param name="min">-3.15</param><param name="max">3.15</param></command_interface>
      <command_interface name="velocity"><param name="min">-10.0</param><param name="max">10.0</param></command_interface>
      <state_interface name="position"/><state_interface name="velocity"/>
    </joint>
    <joint name="j5_arm_joint">
      <command_interface name="position"><param name="min">-3.15</param><param name="max">3.15</param></command_interface>
      <command_interface name="velocity"><param name="min">-10.0</param><param name="max">10.0</param></command_interface>
      <state_interface name="position"/><state_interface name="velocity"/>
    </joint>
    <joint name="j6_arm_joint">
      <command_interface name="position"><param name="min">-3.15</param><param name="max">3.15</param></command_interface>
      <command_interface name="velocity"><param name="min">-10.0</param><param name="max">10.0</param></command_interface>
      <state_interface name="position"/><state_interface name="velocity"/>
    </joint>
  </ros2_control>

  <xacro:lidar_sensor prefix="$(arg prefix)" parent="base_link" frame_id="laser_frame" xyz_offset="0 0 -0.05" rpy_offset="0 0 0" mesh_xyz_offset="0 0 0" mesh_rpy_offset="${-M_PI/2} 0 0" topic_name="scan"/>
  <xacro:imu_sensor prefix="$(arg prefix)" parent="base_link" frame_id="imu" xyz_offset="0 0 0.006" rpy_offset="0 0 0" update_rate="15.0" topic_name="imu/data"/> 
  <xacro:rgbd_camera prefix="$(arg prefix)" camera_name="d435" parent="camera_holder_link" xyz_offset="0.035 0.045 -0.009" rpy_offset="0 0 -1.5708"/>

</robot>